Traceback (most recent call last):
  File "/Library/Frameworks/Python.framework/Versions/3.5/lib/python3.5/site-packages/requests/packages/urllib3/connectionpool.py", line 376, in _make_request
    httplib_response = conn.getresponse(buffering=True)
TypeError: getresponse() got an unexpected keyword argument 'buffering'

During handling of the above exception, another exception occurred:

Traceback (most recent call last):
  File "/Library/Frameworks/Python.framework/Versions/3.5/lib/python3.5/site-packages/requests/packages/urllib3/connectionpool.py", line 559, in urlopen
    body=body, headers=headers)
  File "/Library/Frameworks/Python.framework/Versions/3.5/lib/python3.5/site-packages/requests/packages/urllib3/connectionpool.py", line 378, in _make_request
    httplib_response = conn.getresponse()
  File "/Library/Frameworks/Python.framework/Versions/3.5/lib/python3.5/http/client.py", line 1174, in getresponse
    response.begin()
  File "/Library/Frameworks/Python.framework/Versions/3.5/lib/python3.5/http/client.py", line 282, in begin
    version, status, reason = self._read_status()
  File "/Library/Frameworks/Python.framework/Versions/3.5/lib/python3.5/http/client.py", line 251, in _read_status
    raise RemoteDisconnected("Remote end closed connection without"
http.client.RemoteDisconnected: Remote end closed connection without response

During handling of the above exception, another exception occurred:

Traceback (most recent call last):
  File "/Library/Frameworks/Python.framework/Versions/3.5/lib/python3.5/site-packages/requests/adapters.py", line 370, in send
    timeout=timeout
  File "/Library/Frameworks/Python.framework/Versions/3.5/lib/python3.5/site-packages/requests/packages/urllib3/connectionpool.py", line 609, in urlopen
    _stacktrace=sys.exc_info()[2])
  File "/Library/Frameworks/Python.framework/Versions/3.5/lib/python3.5/site-packages/requests/packages/urllib3/util/retry.py", line 245, in increment
    raise six.reraise(type(error), error, _stacktrace)
  File "/Library/Frameworks/Python.framework/Versions/3.5/lib/python3.5/site-packages/requests/packages/urllib3/packages/six.py", line 309, in reraise
    raise value.with_traceback(tb)
  File "/Library/Frameworks/Python.framework/Versions/3.5/lib/python3.5/site-packages/requests/packages/urllib3/connectionpool.py", line 559, in urlopen
    body=body, headers=headers)
  File "/Library/Frameworks/Python.framework/Versions/3.5/lib/python3.5/site-packages/requests/packages/urllib3/connectionpool.py", line 378, in _make_request
    httplib_response = conn.getresponse()
  File "/Library/Frameworks/Python.framework/Versions/3.5/lib/python3.5/http/client.py", line 1174, in getresponse
    response.begin()
  File "/Library/Frameworks/Python.framework/Versions/3.5/lib/python3.5/http/client.py", line 282, in begin
    version, status, reason = self._read_status()
  File "/Library/Frameworks/Python.framework/Versions/3.5/lib/python3.5/http/client.py", line 251, in _read_status
    raise RemoteDisconnected("Remote end closed connection without"
requests.packages.urllib3.exceptions.ProtocolError: ('Connection aborted.', RemoteDisconnected('Remote end closed connection without response',))

During handling of the above exception, another exception occurred:

Traceback (most recent call last):
  File "agent.py", line 51, in <module>
    main()
  File "agent.py", line 46, in main
    Register(address, port, name)
  File "agent.py", line 23, in Register
    headers = headers)
  File "/Library/Frameworks/Python.framework/Versions/3.5/lib/python3.5/site-packages/requests/api.py", line 109, in post
    return request('post', url, data=data, json=json, **kwargs)
  File "/Library/Frameworks/Python.framework/Versions/3.5/lib/python3.5/site-packages/requests/api.py", line 50, in request
    response = session.request(method=method, url=url, **kwargs)
  File "/Library/Frameworks/Python.framework/Versions/3.5/lib/python3.5/site-packages/requests/sessions.py", line 468, in request
    resp = self.send(prep, **send_kwargs)
  File "/Library/Frameworks/Python.framework/Versions/3.5/lib/python3.5/site-packages/requests/sessions.py", line 576, in send
    r = adapter.send(request, **kwargs)
  File "/Library/Frameworks/Python.framework/Versions/3.5/lib/python3.5/site-packages/requests/adapters.py", line 412, in send
    raise ConnectionError(err, request=request)
requests.exceptions.ConnectionError: ('Connection aborted.', RemoteDisconnected('Remote end closed connection without response',))
